Workbook

Sheet range-0
A1: id | B1: art | C1: year | D1: fr | E1: de | F1: es | G1: it | H1: en | I1: pl | J1: ar | K1: pt | L1: zh | M1: cs | N1: hr | O1: hu | P1: mt | Q1: nl | R1: ro | S1: vi | T1: heiliger | U1: start_datum | V1: end_datum | W1: folder_path | X1: fr | Y1: de | Z1: es | AA1: it | AB1: en | AC1: pl | AD1: ar | AE1: pt | AF1: zh | AG1: cs | AH1: hr | AI1: hu | AJ1: mt | AK1: nl | AL1: ro | AM1: vi | AN1: fr | AO1: de | AP1: es | AQ1: it | AR1: en | AS1: pl | AT1: ar | AU1: pt | AV1: zh | AW1: cs | AX1: hr | AY1: hu | AZ1: mt | BA1: nl | BB1: ro | BC1: vi | BD1: fr | BE1: de | BF1: es | BG1: it | BH1: en | BI1: pl | BJ1: ar | BK1: pt | BL1: zh | BM1: cs | BN1: hr | BO1: hu | BP1: mt | BQ1: nl | BR1: ro | BS1: vi | BT1: fr | BU1: de | BV1: es | BW1: it | BX1: en | BY1: pl | BZ1: ar | CA1: pt | CB1: zh | CC1: cs | CD1: hr | CE1: hu | CF1: mt | CG1: nl | CH1: ro | CI1: vi
A2: advent-2026-lorenz | B2: advent | C2: 2026 | E2: 2026_advent | F2: 2026_adviento | G2: 2026_avvento | H2: 2026_advent | I2: 2026_adwent | J2: 2026_zaman-al-maji | K2: 2026_advento | L2: 2026_jianglinqi | M2: 2026_advent | N2: 2026_dosasce | O2: 2026_advent | P2: 2026_avvent | Q2: 2026_advent | R2: 2026_advent | S2: 2026_mua-vong | T2: Br. Lorenz von der Auferstehung | U2: 2026-11-25 | V2: 2027-01-03 | W2: X:\ALLGEMEIN\0900 Veröffentlichungen\Veröffentlichungen-aktuell\2026 Advent | Y2: Advent 2026 mit Bruder Lorenz von der Auferstehung | AB2: Advent 2026 with Brother Lawrence of the Resurrection | AO2: Üben in der Gegenwart Gottes | BE2: Bruder Laurentius von der Auferstehung, eine zurückhaltende Persönlichkeit des Karmel, war einer der großen Meister des geistlichen Lebens des 17. Jahrhunderts. Seine Lehren, die jüngst von Papst Leo XIV. wieder ins Rampenlicht gerückt wurden, sind erstaunlicherweise immer noch relevant. Dieser demütige Laienbruder lehrt uns, die Gegenwart Gottes in den Mittelpunkt unseres täglichen Lebens zu stellen. Seine Lehre wurzelt in der großen christlichen Tradition und ist eine Antwort auf Jesu Aufruf, „unablässig zu beten“ (Lukas 18,1), und gemäß der Mahnung des heiligen Paulus: „Betet ohne Unterlass“ (1 Thessalonicher 5,17). Für Bruder Lorenz ist der Weg einfach: in jedem Augenblick in der Gegenwart Gottes zu bleiben, egal welchen Berufen wir nachgehen. In dieser Adventszeit laden wir Sie ein, zu entdeckendiese Schule der Gegenwart Gottes, um in einer Beziehung zu wachseneinfacher, selbstsicherer und inniger mit dem Herrn. | BU2: ../de/img/2026_advent_header_DE.jpg
A3: lent-2026-johannes-vom-kreuz | B3: lent | C3: 2026 | D3: https://retraites.carmes-paris.org/careme-2026/careme-2026-st-jean-de-la-croix/ | E3: 2026_fastenzeit | F3: 2026_cuaresma | G3: 2026_quaresima | H3: 2026_lent | I3: 2026_wielki-post | J3: 2026_al-sawm-al-kabir | K3: 2026_quaresma | L3: 2026_sixunqi | M3: 2026_pust | N3: 2026_korizma | O3: 2026_nagybojt | P3: 2026_randan | Q3: 2026_vastentijd | R3: 2026_postul-mare | S3: 2026_mua-chay | T3: Heiliger Johannes vom Kreuz | U3: 2026-02-18 | V3: 2026-04-05 | W3: X:\ALLGEMEIN\0900 Veröffentlichungen\Veröffentlichungen-aktuell\2026 Fastenzeit | X3: Ste Mariam de Jésus Crucifié (1846-1878) | Y3: Fastenzeit 2026 mit dem heiligen Johannes vom Kreuz | Z3: Cuaresma 2026 con San Juan de la Cruz | AA3: Esercizi spirituali online per la Quaresima 2026 con San Giovanni della Croce | AB3: Carmelite Online Lenten Retreat 2026 with Saint John of the Cross | AC3: Karmelitańskie rekolekcje online ze św. Janem od Krzyża Wielki Post 2025 | AD3: صوم ٢٠٢٦ مع القديس يوحنا الصليب من ١٨ شباط إلى ٥ نيسان ٢٠٢٦ | AE3: Quaresma 2026 Com São João da Cruz | AF3: 2026年四旬期——与圣十字若望同行 2026年2月18日至4月5日 | AG3: Doba postní 2026 Online exercicie se svatým Janem od Kříže | AH3: Korizma 2026. Online karmelske duhovne vježbe | AI3: Kármelita online lelkigyakorlat a nagyböjt idején Keresztes Szent János sarutlan kármelita segítségével. | AJ3: Irtir tar-Randan Karmelitan Online 2026 | AK3: Vastentijd 2026 Online retraite: Sint Jan van het Kruis | AL3: Postul Mare Reculegere spirituală carmelitană online Împreună cu Sfântul Ioan al Crucii | AM3: Tĩnh tâm trên mạng trong mùa Chay 2026 của dòng Cát-Minh Chân Trần | AO3: Christus in der Tiefe des Herzens begegnen | AP3: «Encontrar a Cristo en lo más profundo de nuestro corazón» | AQ3: «Incontrare Gesù Cristo nel profondo del nostro cuore» | AR3: Encountering Christ in the Depths of Our Hearts | AS3: „Spotkanie z Jezusem Chrystusem w głębi naszego serca” | AT3: "نلتقي المسيح في أعماق قلبنا" | AU3: “Encontrar Cristo no fundo de nosso coração” | AV3: “在我们心灵深处与耶稣基督相遇” | AW3: „Setkání s Kristem v hloubi našeho srdce“ | AX3: Susresti Krista u dubini svoga srca | AY3: „Találkozzunk Krisztussal a szívünk legmélyén” | AZ3: “Niltaqgħu ma’ Kristu fil-Fond ta’ Qlubna, ma’ San Ġwann tas-Salib” | BA3: “Christus ontmoeten diep in ons hart” | BB3: „Să-L întâlnim pe Cristos în adâncul inimii noastre” | BC3: « gặp Đức Ki-tô tận đáy lòng chúng ta » | BE3: Wir bieten Ihnen Online-Exerzitien in der Schule des heiligen Johannes vom Kreuz an. In diesen Exerzitien werden wir im Lichte der Evangelien unsere Beziehung zu Jesus vertiefen, um im Heiligen Geist wieder zur Vertrautheit mit Ihm und mit Gott Vater in der Tiefe unseres Herzens zu gelangen. Es wird ein Weg der inneren Befreiung sein, auf dem uns Johannes vom Kreuz zuverlässig und sicher führen wird. Er wird uns in einer zunehmend auf das Äußere hin orientierten Welt lehren, wieder in unser tiefstes Inneres einzugehen, wo Christus, der Bräutigam der Kirche, uns begegnen und reinigen will, damit wir mit Ihm im Feuer des Heiligen Geistes zu den innig geliebten Kindern des Vaters werden. | BF3: Te proponemos un retiro online en la escuela de San Juan de la Cruz. A lo largo de este retiro, profundizaremos, a la luz de los Evangelios, en nuestra relación con Jesús para reencontrar, en el Espíritu Santo, nuestra intimidad con Él y con el Padre, en lo más profundo de nuestro corazón. Será un camino de liberación interior en el que Juan de la Cruz será nuestro guía seguro. Él nos enseñará, en un mundo cada vez más exteriorizado, a reencontrar nuestro corazón profundo, allí donde Cristo, Esposo de la Iglesia, quiere encontrarnos y purificarnos, para que con Él nos convirtamos en los hijos amados del Padre, en el fuego del Espíritu Santo. | BG3: Vi proponiamo questi esercizi spirituali online mettendoci alla scuola di san Giovanni della Croce, Carmelitano Scalzo. Durante questa quaresima, approfondiremo, alla luce dei Vangeli, la nostra relazione con Gesù per ritrovare, nello Spirito Santo, l'intimità con Lui e con il Padre nel più profondo del nostro cuore. Sarà un cammino di liberazione interiore nel quale Giovanni della Croce potrà essere la nostra guida sicura. In un mondo sempre più esteriore, ci insegnerà a ritrovare la profondità del nostro cuore, là dove Cristo, Sposo della Chiesa, vuole incontrarci e purificarsi così che diventiamo figli amati del Padre, nel fuoco dello Spirito Santo. | BH3: We invite you to take part in an online retreat guided by Saint John of the Cross. Throughout this retreat, we will deepen our relationship with Jesus in the light of the Gospels. In the Holy Spirit, we will rediscover our intimacy with him and with the Father, in the very depths of our hearts. This retreat will be a path of interior liberation, with John of the Cross as our sure guide. In a world that is increasingly turned outward, he will teach us to rediscover our deepest heart, where Christ, Bridegroom of the Church, desires to meet us and to purify us. Through this purification, in the fire of the Holy Spirit, we may become the beloved children of the Father with him. | BI3: Proponujemy wam te rekolekcje online, ucząc się od św. Jana od Krzyża. Podczas tego Wielkiego Postu, w świetle Ewangelii, pogłębimy naszą relację z Jezusem, aby w Duchu Świętym odnaleźć bliskość z Nim i z Ojcem w głębi naszego serca. Będzie to droga wewnętrznego wyzwolenia, na której Jan od Krzyża będzie naszym pewnym przewodnikiem. W coraz bardziej płytkim świecie nauczy nas on odnaleźć głębię naszego serca, gdzie Chrystus, Oblubieniec Kościoła, chce nas spotkać i oczyścić, abyśmy stali się umiłowanymi dziećmi Ojca rozpalonymi Duchem Świętym. | BJ3: نقترح عليكم رياضة روحيّة عبر الإنترنت في مدرسة القديس يوحنا الصليب. خلال هذه الرياضة سنعمّق، على ضوء الأناجيل، علاقتنا بيسوع فنكشف من جديد وبالروح القدس، في أعماق قلوبنا، علاقتنا الحميمة به وبالآب. سيكون هذا دربًا للتحرر الداخليّ، وسيكون يوحنا الصليب دليلنا الأمين فيه. سيعلّمنا ذلك، في عالم يزداد انعزالاً عن العالم الخارجي، أن نعيد اكتشاف أعماق قلوبنا، حيث يريد المسيح، عريس الكنيسة، أن يلتقي بنا ويطهِّرنا، حتّى نصبح معه أبناء الآب المحبوبين، في نور الروح القدس. | BK3: Nós lhes propomos um retiro online na escola de São João da Cruz. Ao longo desse retiro, aprofundaremos nossa relação com Jesus à luz dos Evangelhos, a fim de encontrar, no Espírito Santo, nossa intimidade com Ele e com o Pai no mais profundo de nosso coração. Será um caminho de libertação interior, no qual João da Cruz será nosso guia seguro. Em um mundo de cada vez mais exterioridade, ele nos ensinará a encontrar nosso coração profundo, onde o Cristo, Esposo da Igreja, quer nos encontrar e nos purificar, para que com Ele nos tornemos os filhos bem-amados do Pai, no fogo do Espírito Santo. | BL3: 我们为您提供这些线上灵修退省，让我们一同进入圣十字若望灵修学校。在这个四旬期里，我们将在福音的光照下，深化与耶稣的关系，为能在圣神内，在我们心灵的最深处，重新寻获与祂及与天父的亲密关系。这将是一段内在自由的旅程，圣十字若望将成为我们可靠的向导。在一个日益外表化的世界里，他将教导我们重新寻回心灵的深度—在那里，教会的新郎基督渴望与我们相遇，并施行净化，好使我们在圣神的火焰中，成为天父所钟爱的子女。 | BM3: Vám nabízíme online duchovní cvičení ve škole svatého Jana od Kříže. Během těchto duchovních cvičení budeme ve světle evangelií prohlubovat náš vztah k Ježíši, abychom v Duchu svatém znovu nalezli důvěrný vztah s Ním a s Otcem v nejhlubším nitru svého srdce. Bude to cesta vnitřního osvobození, na které nám Jan od Kříže bude spolehlivým průvodcem. Bude nás učit, jak v tomto světě, který se stále víc orientuje „ven“, na povrch a vnější zdání, můžeme znovu najít své nejhlubší nitro, kde se s námi chce setkat Kristus, Ženich církve, a chce nás očistit, abychom se spolu s Ním stali milovanými dětmi Otce v ohni Ducha Svatého. | BN3: Predlažemo vam online duhovnu obnovu u školi svetog Ivana od Križa. Tijekom ove duhovne obnove produbljivat ćemo, u svjetlu Evanđelja, naš odnos s Isusom kako bismo, u Duhu Svetom, ponovno otkrili svoju intimnost s Njim i s Ocem, u najdubljoj nutrini našega srca. Bit će to put unutarnjeg oslobođenja, na kojem će nam Ivan od Križa biti siguran vodič. On će nas, u svijetu sve više okrenutom vanjštini, poučiti kako ponovno pronaći dubinu vlastitoga srca, ondje gdje nas Krist, Zaručnik Crkve, želi susresti i pročistiti, kako bismo s Njime postali ljubljena djeca Očeva, u ognju Duha Svetoga. | BO3: A lelkigyakorlat során az evangéliumok fényében mélyítjük el kapcsolatunkat Jézussal, hogy a Szentlélekben újra rátaláljunk a vele és az Atyával való bensőséges közösségre, szívünk legmélyén. Ez a belső felszabadulás útja lesz, amelyen Keresztes Szent János biztos vezetőnk. Megtanít bennünket arra, hogy egy egyre inkább kifelé forduló világban újra felfedezzük szívünk legmélyén, azt a helyet, ahol Krisztus, az Egyház Vőlegénye találkozni akar velünk és meg akar tisztítani bennünket, hogy vele együtt a Szentlélek tüzében az Atya szeretett gyermekeivé váljunk. Készüljünk együtt a húsvétra ezzel a lelkigyakorlattal. | BP3: Nistednukom għal irtir online fl-iskola ta’ San Ġwann tas-Salib. Tul dan l-irtir, fid-dawl tal-Evanġelji, se nsaħħu u napprofondixxu r-relazzjoni tagħna ma’ Ġesù, biex fl-Ispirtu s-Santu nerġgħu nsibu l-intimità tagħna miegħu u mal-Missier, fil-post l-aktar profond ta’ qalbna. Dan l-irtir se jkun mixja ta’ ħelsien interjuri, fejn San Ġwann tas-Salib ikun il-gwida żgura tagħna. F’dinja dejjem aktar orjentata lejn barra, hu jgħallimna nerġgħu nsibu l-qalb profonda tagħna, hemmhekk fejn Kristu, l-Għarus tal-Knisja, jixtieq jiltaqa’ magħna u jippurifikana. F’din il-purifikazzjoni, fin-nar tal-Ispirtu s-Santu, inkunu nistgħu nsiru miegħu wlied maħbuba tal-Missier, skont il-qalb tiegħu. | BQ3: Wij nodigen u uit voor een online retraite in de geest van de heilige Johannes van het Kruis. Tijdens deze retraite verdiepen we, in het licht van het evangelie, onze relatie met Jezus, zodat we in de Heilige Geest de intimiteit met Hem en met de Vader in ons diepste hart mogen ontdekken. Het wordt een weg van innerlijke bevrijding, waarbij Johannes van het Kruis ons als betrouwbare gids begeleidt. In een wereld die steeds meer naar buiten gericht is, leert hij ons opnieuw ons innerlijk centrum te vinden, waar Christus, de Bruidegom van de Kerk, ons wil ontmoeten en zuiveren, opdat wij in het vuur van de Heilige Geest mogen leven als geliefde kinderen van de Vader. Na inschrijving ontvangt u wekelijks een e-mail met het zondagsevangelie, een bezinning voor de week en korte suggesties voor elke dag van de week. | BR3: Vă propunem o reculegere online alături de acest mare Sfânt carmelitan. De-a lungul acestei reculegeri, vom aprofunda, în lumina Evangheliei, relația noastră cu Isus, pentru a regăsi, în Duhul Sfânt, intimitatea noastră cu El și cu Tatăl, în profunzimile inimii noastre. Va fi un drum de eliberare interioară pentru care Sfântul Ioan al Crucii va fi îndrumătorul nostru de încredere. Ne va învăța ca, într-o lume din ce în ce mai exteriorizată, să ne regăsim adâncul inimii, locul unde Cristos, Mirele Bisericii, vrea să ne întâlnească și să ne purifice, astfel încât, împreună cu el să devenim copiii preaiubiți ai Tatălui, prin focul Duhului Sfânt. | BS3: Chúng tôi đề nghị với bạn một tĩnh tâm trên mạng theo trường phái của thánh Gio-an Thánh Giá. Trong suốt cuộc tĩnh tâm, với ánh sáng Tin Mừng, chúng ta sẽ đào sâu mối quan hệ của chúng ta với Chúa Giê-su để trong Chúa Thánh Thần, chúng ta tìm lại sự thân mật với Chúa Giê-su và với Chúa Cha, trong tận đáy lòng chúng ta. Đó sẽ là một con đường giải thoát nội tâm được Thánh Gio-an Thánh Giá hướng dẫn cách chắc chắn. Trong một thế giới càng ngày càng hướng ngoại, thánh nhân sẽ dạy chúng ta tìm lại đáy lòng chúng ta, nơi Chúa Ki-tô, Hôn phu của Giáo Hội, muốn gặp và thanh tẩy chúng ta, để cùng với Người chúng ta trở thành những người con yêu dấu của Chúa Cha, trong lửa Chúa Thánh Thần. | BU3: ../de/img/2026_lent_header_DE.png | BV3: ../es/img/2026_lent_header_ES.png | BW3: ../it/img/2026_lent_header_IT.png | BX3: ../en/img/2026_lent_header_EN.png | BY3: ../pl/img/2026_lent_header_PL.png | BZ3: ../ar/img/2026_lent_header_AR.png | CA3: ../PT/img/2026_lent_header_PT.png | CB3: ../zh/img/2026_lent_header_ZH.png | CC3: ../cs/img/2026_lent_header_CS.png | CD3: ../hr/img/2026_lent_header_HR.png | CE3: ../hu/img/2026_lent_header_HU.png | CF3: ../mt/img/2026_lent_header_MT.png | CG3: ../nl/img/2026_lent_header_NL.png | CH3: ../ro/img/2026_lent_header_RO.png | CI3: ../vi/img/2026_lent_header_VI.png
A4: advent-2025-mirjam-von-jesus-dem-gekreuzigten | B4: advent | C4: 2025 | E4: 2025_advent | F4: 2025_adviento | G4: 2025_avvento | H4: 2025_advent | I4: 2025_adwent | J4: 2025_zaman-al-maji | K4: 2025_advento | L4: 2025_jianglinqi | M4: 2025_advent | N4: 2025_dosasce | O4: 2025_advent | P4: 2025_avvent | Q4: 2025_advent | R4: 2025_advent | S4: 2025_mua-vong | T4: Heilige Mirjam von Jesus, dem Gekreuzigten | U4: 2025-11-26 | V4: 2025-12-25 | W4: X:\ALLGEMEIN\0900 Veröffentlichungen\Veröffentlichungen-aktuell\2025 Advent | X4: Ste Mariam de Jésus Crucifié (1846-1878) | Y4: Advent 2025 mit der heiligen Mirjam von Jesus, dem Gekreuzigten | Z4: Retiro online de Adviento Con Santa María de Jesús Crucificado Carmelita Descalza (1846-1878) | AA4: Esercizi spiritualei online d'Avvento con Santa Mariam di Gesú Crocifisso | AB4: Advent 2025 with St. Mariam of Jesus Crucified | AC4: REKOLEKCJE ADWENTOWE ONLINE Świętą Mariam od Jezusa Ukrzyżowanego Karmelitanką Bosą (1846-1878) | AD4: رياضة روحيّة عبر الإنترنت – زمن المجيء من 26 تشرين الثاني حتى 25 كانون الأوّل 2025 مع القدّيسة مريم يسوع المصلوب الكرمليّة الحافية (1846 – 1878) | AE4: Retiro online de Advento com Sta Miriam de Jesus Crucificado Carmelita Descalça (1846-1878) | AF4: 加尔默罗灵修退省活动 2025年将临期 «玛利安，或上主的贫苦者之路» 与耶稣苦难圣玛利安同行 | AG4: Marie od Ukřižovaného – cesta chudých Páně Online exercicie Advent 2025 | AH4: Došašće 2025. Online karmelske duhovne vježbe | AI4: Online adventi lelkigyakorlat a Keresztre feszített Jézusról nevezett Szent Mirjam sarutlan kármelita szerzetes nővérrel (1846-1878) | AJ4: Irtir onlajn tal-Karmelitani Avvent 2025 Ma’ Santa Marjam ta' Ġesù Msallab | AK4: Advent 2025 Online retraite: St. Mariam van de Gekruisigde Jesus | AL4: Advent 2025 Reculegere spirituală carmelitană online împreună cu Sfânta Mariam a lui Isus Răstignit (1846-1878) | AM4: Tĩnh tâm trên mạng trong mùa Vọng 2025 của dòng Cát-Minh Chân Trần | AN4: Mariam ou la voie des pauvres du Seigneur | AO4: Mariam oder der Weg der Armen des Herrn | AP4: Mariam o el camino de los pobres del Señor | AQ4: « Mariam o la via dei poveri del Signore» | AR4: Mariam, or the Way of the Lord's Poor | AS4: „Mariam, czyli droga ubogich Pana” | AT4: مريم أو درب فقراء الربّ | AU4: «Miriam ou o caminho dos pobres do Senhor» | AV4: «玛利安，或上主的贫苦者之路» | AW4: Marie od Ukřižovaného – cesta chudých Páně | AX4: "Mirjam - put siromaha Gospodnjih" | AY4: « Mirjam, avagy az Úr szegényeinek útja » | AZ4: "Marjam, jew it-Triq tal-Foqra tal-Mulej" | BA4: “De weg van de armen van de Heer” | BB4: „Mariam sau calea săracilor Domnului” | BC4: Cùng bước với Ma-ri-am | BE4: Die heilige Maria von Jesus, dem Gekreuzigten (1846-1878), die „kleine Araberin“, geboren im Heiligen Land, Analphabetin und demütige Karmelitin, gründete dennoch mehrere Karmelklöster im Orient und in Indien. Ihr schlichtes Leben im Glanz der Heiligkeit, geführt vom Heiligen Geist, lädt uns ein, uns von Jesus lieben und verwandeln zu lassen … | BF4: Santa María de Jesús Crucificado (1846-1878), la « Arabita», nacida en Tierra Santa, humilde carmelita analfabeta, fundó sin embargo varios Carmelos en Oriente y en la India. Su vida sencilla y luminosa, guiada por el Espíritu Santo, nos invita a dejarnos amar y transformar por Jesús... | BG4: Santa Mariam di Gesù Crocifisso (1846-1878), la “piccola araba”, nata in Terra Santa, umile carmelitana illetterata, ha fondato alcuni Carmeli in Israele e in India. La sua vita semplice e luminosa, guidata dallo Spirito Santo, ci invita a farci amare e trasformare da Gesù… | BH4: Saint Mariam of Jesus Crucified (1846-1878), the "Little Arab," born in the Holy Land, a humble Carmelite who learned to read and write as an adult, founded Carmelite monasteries in the Holy Land and India. Her simple and radiant life, led by the Holy Spirit, invites us to let ourselves be loved and transformed by Jesus. | BI4: Święta Mariam od Jezusa Ukrzyżowanego (1846-1878), zwana „Małą Arabką”, urodzona w Ziemi Świętej, była pokorną niepiśmienną karmelitanką bosą. Założyła jednak kilka klasztorów karmelitańskich na Bliskim Wschodzie i w Indiach. Jej proste i pełne światła życie, kierowane przez Ducha Świętego, zachęca nas, abyśmy pozwolili Jezusowi nas kochać i przemieniać... | BJ4: القدّيسة مريم يسوع المصلوب (1846 – 1878)، الملقّبة بـ «العربيّة الصغيرة»، وُلدت في الأرض المقدّسة، وبرغم تواضعها وأميّتها، أسّست عدّة أديرة للكرمل في الشرق والهند. إنّ حياتها البسيطة والمضيئة، الّتي قادها الروح القدس، تدعونا إلى أن نسلّم ذواتنا لمحبّة يسوع كي يحوّلنا... | BK4: Santa Maria (Miriam) de Jesus Crucificado (1846-1878), a «pequena árabe», nascida na Terra Santa, humilde carme lita, analfabeta, fundou vários Carmelos no Oriente e na Índia. A sua vida simples e luminosa, guiada pelo Espírito Santo, convida-nos a deixar-nos amar e transformar por Jesus... | BL4: 今年将陪伴我们度过将临期、走向圣诞的是圣女耶稣苦难玛利安（St. Mariam of Jesus Crucified，原名Mariam Baouardy），玛丽安包迪，这位出生于巴勒斯坦的“小阿拉伯人”。圣玛利安（1846-1878）是一位不识字的谦卑加尔默罗会修女，曾在以色列和印度创立了数座加尔默罗会隐修院。她简单而光辉的一生，充满了圣神的指引，她邀请我们体验被耶稣所爱并被祂转变…… | BM4: Zveme vás ke karmelským adventním exerciciím. Letos jsme slavili 150. výročí založení kláštera karmelitek v Betlémě. A tak bude tento advent naší průvodkyní zakladatelka tohoto kláštera – svatá Marie od Ukřižovaného, „Malá Arabka“, narozená ve Svaté zemi, pokorná karmelitánka, která neuměla číst a psát, založila několik karmelitánských klášterů na Východě a v Indii. | BN4: Sveta Mirjam od Krista Raspetoga (1846.–1878.), „mala Arapkinja“, rođena u Svetoj zemlji, ponizna i nepismena karmelićanka, osnovala je nekoliko karmelskih samostana u Izraelu i Indiji. Njezin jednostavan i svjetlom ispunjen život, vođen Duhom Svetim, poziva nas da dopustimo Isusu da nas ljubi i preobražava… | BO4: A Magyar Sarutlan Kármelita Delegáció és a Világban Élő Kármeliták arra hívják Önt, hogy ebben az adventi időszakban engedje meg, hogy a Keresztre feszített Jézusról nevezett Szent Mirjam kísérje Önt. A „kis arab lány”, aki a Szentföldön született, alázatos és írástudatlan kármelita volt, mégis több kármelita kolostort alapított a Közel-Keleten és Indiában. Egyszerű élete a szentség fényében, a Szentlélek vezetése alatt arra hív bennünket,hogy hagyjuk magunkat Jézus által szeretni és átformálni. | BP4: Din is-sena, Santa Marjam (Baouardy) ta' Ġesù Msallab, l-"Għarbija ċkejkna" imwielda fil-Palestina, se tiggwidana fil-vjaġġ tal-Avvent tagħna lejn il-Milied. Santa Marjam (1846-1878), Karmelitana umli li tgħallmet taqra u tikteb bħala adulta, waqqfet monasteri Karmelitani fl-Indja u l-Art Imqaddsa. Il-ħajja sempliċi u radjanti tagħha, immexxija mill-Ispirtu s-Santu, tistiedinna nħallu lilna nfusna ninħabbu u nitbiddlu minn Ġesù... | BQ4: Dit jaar zal een kleine heilige karmelietes geboren in het land van Jezus, heilige Mariam van de Gekruisigde Jezus, ons vergezellen. Tien jaar geleden, op 17 mei 2015, werd ze namelijk heilig verklaard door paus Franciscus. Haar hele leven is een Woord van God. De boodschap die Mariam ons nalaat, met haar zeer beeldende taal die ons dichter bij de Bijbel brengt, is een oproep voor ons, om te leren ons te laten liefhebben door Jezus en ons te laten leiden door de Heilige Geest in een wereld waar alle waarden instorten, waardoor ruimte komt voor een gevoel van onveiligheid. Mariam van de Gekruisigde Jezus combineert nederigheid en armoede met verbluffende bovennatuurlijke en mystieke ervaringen. Deze tegenstellingen worden beleefd in een hart dat volledig is overgeleverd aan de liefde van God, in een totale gehoorzaamheid aan zijn wil, een maagdelijk en transparant hart voor de genade van God, beschikbaar voor de werking van de Geest, die haar geleidelijk configureert tot de Gekruisigde Jezus wiens naam zij draagt. | BR4: Anul acesta, Sfânta Mariam (Bouarday) a lui Isus Răstignit, „mica arabă” născută în Palestina, ne va însoți în călătoria noastră de Advent către Crăciun. Sfânta Mariam (1846-1878), o călugăriță carmelitană umilă și analfabetă, a fondat mai multe mănăstiri carmelitane în Israel și India. | BS4: Nếu bạn đăng ký theo mẫu dưới đây, bạn sẽ nhận một e-mail miễn phí mỗi thứ sáu: bạn sẽ có thể nhận bản văn dưới dạng pdf. Nội dung suy niệm xu61t phát từ các bài đọc chúa nhật để giúp bạn học với thánh Ma-ri-am . Một lịch mùa Vọng sẽ cũng giúp bạn được nuôi dưỡng hằng ngày, từ thứ hai đến thứ bảy. | BU4: ../de/img/AD25_header_DE.png | BV4: ../es/img/2025_advent_header_ES.png | BW4: ../it/img/2025_advent_header_IT.jpg | BX4: ../en/img/2025_advent_header_EN.png | BY4: ../pl/img/2025_advent_header_PL.png | BZ4: ../ar/img/2025_advent_header_AR.png | CA4: ../pt/img/2025_advent_header_PT.png | CB4: ../zh/img/2025_advent_header_ZH.jpg | CC4: ../cs/img/2025_advent_header_CS.jpg | CD4: ../hr/img/2025_advent_header_HR.jpg | CE4: ../hu/img/2025_advent_header_HU.jpg | CF4: ../mt/img/2025_advent_header_MT.jpg | CG4: ../nl/img/2025_advent_header_NL.png | CH4: ../ro/img/2025_advent_header_RO.jpg | CI4: ../vi/img/2025_advent_header_VI.jpg
A5: lent-2025-therese-von-lisieux | B5: lent | C5: 2025 | D5: https://retraites.carmes-paris.org/careme-2025/careme-2025-st-jean-de-la-croix/ | E5: 2025_fastenzeit | F5: 2025_cuaresma | G5: 2025_quaresima | H5: 2025_lent | I5: 2025_wielki-post | J5: 2025_al-sawm-al-kabir | K5: 2025_quaresma | L5: 2025_sixunqi | M5: 2025_pust | N5: 2025_korizma | O5: 2025_nagybojt | P5: 2025_randan | Q5: 2025_vastentijd | R5: 2025_postul-mare | S5: 2025_mua-chay | T5: Heilige Thérèse von Lisieux | U5: 2025-03-05 | V5: 2025-04-27 | W5: X:\ALLGEMEIN\0900 Veröffentlichungen\Veröffentlichungen-aktuell\2025 Fasten | X5: Carême 2025 | Y5: Fastenzeit 2025 mit Thérèse von Lisieux und das Östergeheimnis | AA5: Esercizi spirituali online per la Quaresima 2025 con Santa Teresina di Lisieux | AF5: 2025年四旬期在线灵修由赤足加尔默罗会及其出版社主办 | AN5: Thérèse de Lisieux et le mystère pascal | AO5: „Aus Liebe sterben, das ist meine Hoffnung“ | AQ5: Teresa di Lisieux e il mistero pasquale | AV5: 里修德兰与复活节的奥秘与里修德圣女小德兰一起 | BE5: Die heilige Thérèse von Lisieux wird uns in sechs Schritten zur Osterfreude führen: - 1. Sonntag: „Selig jener, der würdig erachtet wurde, Anfechtung zu erleiden!“ - 2. Sonntag: „O [Heiliges] Antlitz, schöner als die Lilien und Rosen im Frühling!“ - 3. Sonntag: „Ich fühlte ein großes Verlangen, für die Bekehrung der Sünder zu arbeiten“ - 4. Sonntag: „Hätte ich auch alle begehbaren Sünden auf dem Gewissen ...“ - 5. Sonntag: „Eine arme Sünderin wie ich“ - Karwoche: „Schau Jesus ins Antlitz ... Da wirst du sehen, wie er uns liebt!“ - Ostern: „Dies ist mein Himmel ... dies ist meine Bestimmung: Leben aus Liebe!!!...“ Jeden Freitag erhalten Sie eine E-Mail-Nachricht: Dort können Sie den Text herunterladen (in drei Formaten: PDF, Word, PDF im Handyformat) oder die Audio-Version als Podcast anhören. Der Inhalt der Betrachtung wird vom Sonntagsevangelium ausgehen und uns in die Schule der heiligen Thérèse von Lisieux führen. Ein Fastenkalender (Zitate und Bilder) wird Sie außerdem jeden Tag, von Montag bis Samstag, durch geistliche Impulse inspirieren. | BG5: I Carmelitani Scalzi e le Edizioni OCD vi invitano a lasciarvi accompagnare durante questa Quaresima da S. Teresina di Lisieux - Teresa del Volto Santo, Teresa davanti al Mistero Pasquale. In questo anno giubilare 2025 celebreremo il centenario della sua canonizzazione (17 maggio). Rispondiamo con gioia all'invito di Papa Francesco a essere pellegrini della speranza. | BL5: 赤足加尔默罗会和加尔默罗出版社邀请您在这个四旬期期间，让里修的圣女小德兰 | BT5: ../img/FS25_header_FR.png | BU5: ../de/img/FS25_header_DE.png | BV5: ../es/img/FS25_header_ES.png | BW5: ../it/img/2025_lent_header_IT.png | BX5: ../img/FS25_header_EN.png | BY5: ../img/FS25_header_PL.png | BZ5: ../img/FS25_header_AR.png | CA5: ../img/FS25_header_PT.png | CB5: ../zh/img/2025_lent_header_ZH.png | CC5: ../img/FS25_header_CS.png | CD5: ../img/FS25_header_HR.png | CE5: ../img/FS25_header_HU.png | CF5: ../img/FS25_header_MT.png | CG5: ../img/FS25_header_NL.png | CH5: ../img/FS25_header_RO.png | CI5: ../img/FS25_header_VI.png
A6: advent-2024-therese-von-lisieux | B6: advent | C6: 2024 | E6: 2024_advent | F6: 2024_adviento | G6: 2024_avvento | H6: 2024_advent | I6: 2024_adwent | J6: 2024_zaman-al-maji | K6: 2024_advento | L6: 2024_jianglinqi | M6: 2024_advent | N6: 2024_dosasce | O6: 2024_advent | P6: 2024_avvent | Q6: 2024_advent | R6: 2024_advent | S6: 2024_mua-vong | T6: Heilige Thérèse von Lisieux | U6: 2024-11-27 | V6: 2025-01-05 | W6: X:\ALLGEMEIN\0900 Veröffentlichungen\Veröffentlichungen-aktuell\2024 Advent | X6: Avent 2024 | Y6: Advent 2024 mit der Hl. Thérèse vom Kind Jesu | AA6: Esercizi spirituali online per l'Avvento 2024 con S.ta Teresina di Lisieux | AN6: « Accueillir Dieu comme des enfants » avec Thérèse de Lisieux | AO6: „Kind sein vor Gott“ | AQ6: Accogliere Dio come bambini | BE6: Diese Online-Exerzitien wollen in den Geist und das Gebet der Jüngsten unter allen Kirchenlehrern einführen, deren Geburtstag sich letztes Jahr zum 150. Mal jährte: die hl. Thérèse vom Kinde Jesus (von Lisieux). Wir werden dies tun, indem wir uns in erster Linie auf die Schriften der Heiligen stützen, die uns ein umfangreiches schriftliches Werk hinterlassen hat. Doch diese erklären nicht alles. Thérèses fulminante Berufung kann nur vor dem Hintergrund des unergründlichen Geheimnisses, von dem ihr ganzes Leben Zeugnis ablegt, vollständig verstanden werden: dem der göttlichen Barmherzigkeit. | BG6: Questo ritiro online vuole aiutarvi a entrare nello spirito e nella preghiera del più giovane Dottore della Chiesa, di cui l'anno scorso abbiamo celebrato il 150° compleanno. Lo faremo soprattutto attingendo agli scritti della santa, che ci ha lasciato un'abbondante opera scritta. Ma questo non spiega tutto. Il destino folgorante di Thérèse può essere pienamente compreso solo alla luce del Mistero insondabile di cui tutta la sua vita è testimone: quello della Divina Misericordia. | BT6: ../img/AD24_header_FR.png | BU6: ../de/img/AD24_header_DE.png | BV6: ../img/AD24_header_ES.png | BW6: ../it/img/2024_advent_header_IT.png | BX6: ../img/AD24_header_EN.png | BY6: ../img/AD24_header_PL.png | BZ6: ../img/AD24_header_AR.png | CA6: ../img/AD24_header_PT.png | CB6: ../img/AD24_header_ZH.png | CC6: ../img/AD24_header_CS.png | CD6: ../img/AD24_header_HR.png | CE6: ../img/AD24_header_HU.png | CF6: ../img/AD24_header_MT.png | CG6: ../img/AD24_header_NL.png | CH6: ../img/AD24_header_RO.png | CI6: ../img/AD24_header_VI.png
A7: lent-2024-pater-jacques-de-jesus | B7: lent | C7: 2024 | D7: https://retraites.carmes-paris.org/careme-2024/careme-2024-st-jean-de-la-croix/ | E7: 2024_fastenzeit | F7: 2024_cuaresma | G7: 2024_quaresima | H7: 2024_lent | I7: 2024_wielki-post | J7: 2024_al-sawm-al-kabir | K7: 2024_quaresma | L7: 2024_sixunqi | M7: 2024_pust | N7: 2024_korizma | O7: 2024_nagybojt | P7: 2024_randan | Q7: 2024_vastentijd | R7: 2024_postul-mare | S7: 2024_mua-chay | T7: Pater Jacques von Jesus | U7: 2024-02-14 | V7: 2024-04-07 | W7: X:\ALLGEMEIN\0900 Veröffentlichungen\Veröffentlichungen-aktuell\2024 Fasten | X7: Carême 2024 | Y7: Fastenzeit 2024 mit Pater Jacuqes von Jesus (1900-1945) | Z7: Cuaresma 2024 Con el Padre Jacobo de Jesús (Lucien Bunel) | AA7: La Quaresima 2024 con p. Jacques di Gesù (1900-1945) | AN7: Par la croix vers la lumière avec le Père Jacques de Jésus (1900-1945) | AO7: Durch das Kreuz zum Licht | AP7: Por la Cruz a la Luz | AQ7: Attraverso la croce verso la luce | BE7: „Durch das Kreuz zum Licht“: So lautet der Anfang der Worte, die Pater Jacques von Jesus im März 1945 im Konzentrationslager Gusen (Österreich) mit Bleistift in ein Notizbuch kritzelte. Sie haben den Wert eines geistlichen Testaments. Dieser bemerkenswerte Erzieher, der im Januar 1944 im Karmeliterkloster von Avon von der Gestapo verhaftet worden war (ein Vorfall, der in dem Film „Auf Wiedersehen, Kinder“ von Louis Malle aufgegriffen wird) und dessen Seligsprechungsprozess im Gange ist, wird uns einen wirkkräftigen Fastenweg aufzeigen, um dem Licht Christi entgegenzugehen. | BF7: ¡Prepárate para la Cuaresma junto con los Carmelitas Descalzos "Por la Cruz a la Luz": en marzo de 1945, en el campo de concentración de Gusen, el Padre Jacobo de Jésus garabateó a lápiz estas primeras palabras convertidas en testamento espiritual. Detenido por la Gestapo en enero de 1944 en el convento de los Carmelitas de Avon (escena evocada en la película de Louis Malle "Adios, muchachos"), este destacado educador, cuyo proceso de beatificación está actualmente en curso, nos abrirá un vigoroso sendero cuaresmal para caminar hacia la luz de Cristo. | BG7: «Attraverso la Croce verso la Luce»: nel marzo 1945, nel campo di concentramento di Gusen, padre Jacques di Gesù scarabocchia a matita su della carta queste prime parole che valgono come un testamento spirituale. Arrestato dalla Gespapo nel gennaio 1944, nel convento carmelitano di Avon (Francia), scena poi evocata nel film Arrivederci ragazzi di Louis Malle, questo educatore eccezionale, di cui è in corso la causa di beatifcazione, ci aprirà un vigoroso cammino di quaresima per camminare verso la luce di Cristo. | BT7: ../img/2024_lent_header_FR.png | BU7: ../de/img/2024_lent_header_DE.png | BV7: ../es/img/2024_lent_header_ES.png | BW7: ../it/img/2024_lent_header_IT.png | BX7: ../en/img/2024_lent_header_EN.png | BY7: ../img/2024_lent_header_PL.png | BZ7: ../ar/img/2024_lent_header_AR.png | CA7: ../img/2024_lent_header_PT.png | CB7: ../img/2024_lent_header_ZH.png | CC7: ../img/2024_lent_header_CS.png | CD7: ../img/2024_lent_header_HR.png | CE7: ../img/2024_lent_header_HU.png | CF7: ../img/2024_lent_header_MT.png | CG7: ../img/2024_lent_header_NL.png | CH7: ../img/2024_lent_header_RO.png | CI7: ../img/2024_lent_header_VI.png
A8: advent-2023-teresa-de-los-andes | B8: advent | C8: 2023 | E8: 2023_advent | F8: 2023_adviento | G8: 2023_avvento | H8: 2023_advent | I8: 2023_adwent | J8: 2023_zaman-al-maji | K8: 2023_advento | L8: 2023_jianglinqi | M8: 2023_advent | N8: 2023_dosasce | O8: 2023_advent | P8: 2023_avvent | Q8: 2023_advent | R8: 2023_advent | S8: 2023_mua-vong | T8: Heilige Teresa de Los Andes | U8: 2023-11-29 | V8: 2023-12-25 | W8: X:\ALLGEMEIN\0900 Veröffentlichungen\Veröffentlichungen-aktuell\2023 Advent | X8: Avent 2023 | Y8: Advent 2023 mit der heiligen Teresa de Los Andes (1900-1920) | AA8: L’Avvento 2023 con S. Teresa di Los Andes | AN8: S’enraciner dans la Joie Divine avec Ste Thérèse des Andes (1900-1920) | AO8: Leben in der Göttlichen Freude | AQ8: Radicarsi nella gioia di Dio | BE8: „Gott ist unendliche Freude." Dieser berühmte Ausspruch der heiligen Teresa de Los Andes (1900-1920), der ersten Chilenin, die heiliggesprochen wurde, ist das Leitmotiv für diese Exerzitien im Advent 2023: Ja, Gott ist sehr viel liebenswürdiger, schöner und liebevoller als wir im Allgemeinen denken! Teresa wird uns dies erkennen lassen, indem sie uns das Beispiel einer liebenswürdigen Heiligkeit vor Augen führt und uns leicht verständliche Ratschläge gibt, damit auch wir unser Leben in der göttlichen Freude verankern können. In ihrer Schule werden wir erkennen, dass wir – an der Seite des göttlichen Neugeborenen – zu einer frohen Heiligkeit gelangen können … | BG8: «Dio è gioia infinita». Questa famosa affermazione di santa Teresa di Los Andes (1900-1920), prima cilena ad essere canonizzata, dà il tono agli ESERCIZI SPIRITUALI ONLINE per l’Avvento 2023: sì, Dio è molto più amabile, più bello, più amorevole di quanto generalmente non lo si reputi! Teresa ce lo farà scoprire mostrandoci l’esempio di una santità affabile e condividendo con noi consigli accessibili perché ci radichiamo a nostra volta nella gioia divina. Alla sua scuola, constateremo che quella santità gioiosa, a fianco del Nuovo Nato, ci è accessibile. | BT8: ../img/2023_advent_header_FR.png | BU8: ../de/img/2023_advent_header_DE.png | BV8: ../img/2023_advent_header_ES.png | BW8: ../it/img/2023_advent_header_IT.jpg | BX8: ../img/2023_advent_header_EN.png | BY8: ../img/2023_advent_header_PL.png | BZ8: ../img/2023_advent_header_AR.png | CA8: ../img/2023_advent_header_PT.png | CB8: ../img/2023_advent_header_ZH.png | CC8: ../img/2023_advent_header_CS.png | CD8: ../img/2023_advent_header_HR.png | CE8: ../img/2023_advent_header_HU.png | CF8: ../img/2023_advent_header_MT.png | CG8: ../img/2023_advent_header_NL.png | CH8: ../img/2023_advent_header_RO.png | CI8: ../img/2023_advent_header_VI.png
A9: lent-2023-oraison-weg-der-kindlichen-berufung | B9: lent | C9: 2023 | D9: https://retraites.carmes-paris.org/careme-2023/careme-2023-st-jean-de-la-croix/ | E9: 2023_fastenzeit | F9: 2023_cuaresma | G9: 2023_quaresima | H9: 2023_lent | I9: 2023_wielki-post | J9: 2023_al-sawm-al-kabir | K9: 2023_quaresma | L9: 2023_sixunqi | M9: 2023_pust | N9: 2023_korizma | O9: 2023_nagybojt | P9: 2023_randan | Q9: 2023_vastentijd | R9: 2023_postul-mare | S9: 2023_mua-chay | T9: Die Heiligen des Karmel | U9: 2023-02-22 | V9: 2023-04-16 | W9: X:\ALLGEMEIN\0900 Veröffentlichungen\Veröffentlichungen-aktuell\2023 Fastenzeit | X9: Carême 2023 | Y9: Fastenzeit 2023: Das Gebet | AA9: Quaresima & Pasqua 2023: La preghiera | AN9: « L’oraison » Chemin pour vivre notre vocation filiale | AO9: Das Gebet - ein Weg, unsere Berufung als Kind Gottes zu leben | AQ9: La preghiera: vivere la vocazione di figli di Dio | BE9: „Kinder Gottes: Wir sind es bereits im Keim durch unsere Taufe. Aber wie können wir unsere tiefe Berufung, für Gott Söhne und Töchter zu werden, voll und ganz verwirklichen? Das Gebet, das persönliche Gebet ist ein bevorzugter Weg für diese Neuschöpfung in Christus. Diese Exerzitien in der Fastenzeit werden uns helfen, unser geistliches Leben tiefgreifend zu erneuern, damit wir uns an der Ostergnade in kindlicher Dankbarkeit erfreuen können!" | BG9: Figli di Dio: grazie al battesimo già lo siamo. Ma come fare per vivere pienamente questa nostra profonda vocazione di diventare figli di Dio? La preghiera mentale, che è una preghiera silenziosa e personale, è un cammino privilegiato per diventare e crescere come figli di Dio in Gesù Cristo. Questi «esercizi spirituali online» quaresimali ci aiuteranno a rinnovare la nostra vita spirituale, in profondità, così da fare esperienza della Pasqua colmi della gratitudine propria ai figli di Dio! | BT9: ../img/2023_lent_header_FR.png | BU9: ../de/img/2023_lent_header_DE.png | BV9: ../img/2023_lent_header_ES.png | BW9: ../it/img/2023_lent_header_IT.png | BX9: ../img/2023_lent_header_EN.png | BY9: ../img/2023_lent_header_PL.png | BZ9: ../img/2023_lent_header_AR.png | CA9: ../img/2023_lent_header_PT.png | CB9: ../img/2023_lent_header_ZH.png | CC9: ../img/2023_lent_header_CS.png | CD9: ../img/2023_lent_header_HR.png | CE9: ../img/2023_lent_header_HU.png | CF9: ../img/2023_lent_header_MT.png | CG9: ../img/2023_lent_header_NL.png | CH9: ../img/2023_lent_header_RO.png | CI9: ../img/2023_lent_header_VI.png
A10: advent-2022-gott-in-unserem-leben | B10: advent | C10: 2022 | E10: 2022_advent | F10: 2022_adviento | G10: 2022_avvento | H10: 2022_advent | I10: 2022_adwent | J10: 2022_zaman-al-maji | K10: 2022_advento | L10: 2022_jianglinqi | M10: 2022_advent | N10: 2022_dosasce | O10: 2022_advent | P10: 2022_avvent | Q10: 2022_advent | R10: 2022_advent | S10: 2022_mua-vong | T10: Die Heiligen des Karmel | U10: 2022-11-23 | V10: 2023-01-01 | W10: X:\ALLGEMEIN\0900 Veröffentlichungen\Veröffentlichungen-aktuell\2022 Advent | X10: Avent 2022 | Y10: Advent 2022 in der Schule der Heiligen des Karmel | AN10: Accueillir la Présence de Dieu dans nos vies | AO10: Die Gegenwart Gottes in unserem Leben erfahren | BE10: Das Weihnachtsgeheimnis ist das Geheimnis Gottes, der sich in unserem Menschsein zu unserer Erlösung gegenwärtig macht. Vor 2000 Jahren in der Krippe von Bethlehem anwesend, ist Christus Jesus hier und jetzt, mitten unter uns und in jedem von uns gegenwärtig. Während dieser Einkehrtage im Advent werden wir uns in die Schule der Heiligen des Karmel begeben, um diese Gegenwart Gottes in unserem Leben auf erneuerte Weise zu empfangen. Gehen wir "auf dieser wunderbaren Straße der Gegenwart Gottes"! | BT10: ../img/AD22_header_FR.png | BU10: ../de/img/AD22_header_DE.png | BV10: ../img/AD22_header_ES.png | BW10: ../it/img/AD22_header_IT.png | BX10: ../img/AD22_header_EN.png | BY10: ../img/AD22_header_PL.png | BZ10: ../img/AD22_header_AR.png | CA10: ../img/AD22_header_PT.png | CB10: ../img/AD22_header_ZH.png | CC10: ../img/AD22_header_CS.png | CD10: ../img/AD22_header_HR.png | CE10: ../img/AD22_header_HU.png | CF10: ../img/AD22_header_MT.png | CG10: ../img/AD22_header_NL.png | CH10: ../img/AD22_header_RO.png | CI10: ../img/AD22_header_VI.png
A11: lent-2022-barmherzigkeit-gottes-mit-den-heiligen-des-karmels | B11: lent | C11: 2022 | D11: https://retraites.carmes-paris.org/careme-2022/careme-2022-st-jean-de-la-croix/ | E11: 2022_fastenzeit | F11: 2022_cuaresma | G11: 2022_quaresima | H11: 2022_lent | I11: 2022_wielki-post | J11: 2022_al-sawm-al-kabir | K11: 2022_quaresma | L11: 2022_sixunqi | M11: 2022_pust | N11: 2022_korizma | O11: 2022_nagybojt | P11: 2022_randan | Q11: 2022_vastentijd | R11: 2022_postul-mare | S11: 2022_mua-chay | T11: Die Heiligen des Karmel | U11: 2022-03-02 | V11: 2022-04-24 | W11: X:\ALLGEMEIN\0900 Veröffentlichungen\Veröffentlichungen-aktuell\2022 Fasten | X11: Carême 2022 | Y11: Fastenzeit 2022: Gottes Barmherzigkeit leben mit den Heiligen des Karmel | AN11: Vivre la Miséricorde de Dieu avec les saints du Carmel | AO11: Die Barmherzigkeit Gottes leben | BE11: Folgende Persönlichkeiten aus dem Karmel werden uns etwas zum Thema Gottesbarmherzigkeit sagen: hl. Teresa von Aila hl. Johannes vom Kreuz Lorenz von der Auferstehung hl. Thérèse von Lisieux hl. Elisabeth von der Dreifaltigkeit hl. Teresa von los Andes | BT11: ../img/FS22_header_FR.png | BU11: ../de/img/FS22_header_DE.jpg | BV11: ../img/FS22_header_ES.png | BW11: ../it/img/FS22_header_IT.png | BX11: ../img/FS22_header_EN.png | BY11: ../img/FS22_header_PL.png | BZ11: ../img/FS22_header_AR.png | CA11: ../img/FS22_header_PT.png | CB11: ../img/FS22_header_ZH.png | CC11: ../img/FS22_header_CS.png | CD11: ../img/FS22_header_HR.png | CE11: ../img/FS22_header_HU.png | CF11: ../img/FS22_header_MT.png | CG11: ../img/FS22_header_NL.png | CH11: ../img/FS22_header_RO.png | CI11: ../img/FS22_header_VI.png
A12: advent-2021-kindheit-der-seele | B12: advent | C12: 2021 | E12: 2021_advent | F12: 2021_adviento | G12: 2021_avvento | H12: 2021_advent | I12: 2021_adwent | J12: 2021_zaman-al-maji | K12: 2021_advento | L12: 2021_jianglinqi | M12: 2021_advent | N12: 2021_dosasce | O12: 2021_advent | P12: 2021_avvent | Q12: 2021_advent | R12: 2021_advent | S12: 2021_mua-vong | T12: Heilige Thérèse von Lisieux | U12: 2021-11-26 | V12: 2022-01-02 | W12: X:\ALLGEMEIN\0900 Veröffentlichungen\Veröffentlichungen-aktuell\2021 Advent | X12: Avent 2021 | Y12: Advent 2021 mit der hl. Thérèse von Lisieux und Maria Montessori | AN12: "L' enfance de l’âme " Avec sainte Thérèse de l’Enfant-Jésus et Maria Montessori | AO12: "Die Kindschaft der Seele" Unser Morgenrot Wecken | BE12: Die heilige Thérèse vom Kinde Jesus (1873-1897) und Maria Montessori (1870-1952) sind beide Doktoren. Die eine führt die Kirche zur Kindschaft, die andere das Kind zur Kirche. Als Frauen und Prophetinnen haben sie aus der Quelle desselben Evangeliums geschöpft. Durch ihre Stimmen, die im Wechsel gleichsam als Echo widerhallen, lüftet Gott den geheimnisvollen Schleier seines Antlitzes, das den Kleinen zugetan ist. | BT12: ../img/AD21_header_FR.png | BU12: ../de/img/AD21_header_DE.jpg | BV12: ../img/AD21_header_ES.png | BW12: ../it/img/AD21_header_IT.png | BX12: ../img/AD21_header_EN.png | BY12: ../img/AD21_header_PL.png | BZ12: ../img/AD21_header_AR.png | CA12: ../img/AD21_header_PT.png | CB12: ../img/AD21_header_ZH.png | CC12: ../img/AD21_header_CS.png | CD12: ../img/AD21_header_HR.png | CE12: ../img/AD21_header_HU.png | CF12: ../img/AD21_header_MT.png | CG12: ../img/AD21_header_NL.png | CH12: ../img/AD21_header_RO.png | CI12: ../img/AD21_header_VI.png
A13: lent-2021-therese-von-avila | B13: lent | C13: 2021 | D13: https://retraites.carmes-paris.org/careme-2021/careme-2021-st-jean-de-la-croix/ | E13: 2021_fastenzeit | F13: 2021_cuaresma | G13: 2021_quaresima | H13: 2021_lent | I13: 2021_wielki-post | J13: 2021_al-sawm-al-kabir | K13: 2021_quaresma | L13: 2021_sixunqi | M13: 2021_pust | N13: 2021_korizma | O13: 2021_nagybojt | P13: 2021_randan | Q13: 2021_vastentijd | R13: 2021_postul-mare | S13: 2021_mua-chay | T13: Heilige Teresa von Ávila | W13: X:\ALLGEMEIN\0900 Veröffentlichungen\Veröffentlichungen-aktuell\2021 Fasten | X13: Carême 2021 | Y13: Fastenzeit 2021 mit der Heilige Teresa von Ávila | Z13: Cuaresma 2021 con Santa Teresa | AN13: Marcher de demeures en demeures avec sainte Thérèse d’Ávila | AO13: Tretet ein in die Burg Eurer Seele... | AP13: Caminando de morada en morada | BE13: Es war mitten in einer Krise, als die heilige Teresa von Ávila (1515-1582) ihr geistliches Meisterwerk, das Buch der Wohnungen der Inneren Burg, schrieb. Während ihr gesamtes Werk als Gründerin des Karmel in sich zusammenzufallen scheint, schöpft sie ihre Energie aus ihrer inneren Burg. In unserem Kontext der Gesundheits- und Wirtschaftskrise kann uns die ‘Madre’ in dieser Fastenzeit helfen, zu entdecken, dass unsere Stärke im Inneren liegt. Mit dieser Kirchenlehrerin gehen wir durch die Burg von Wohnung zu Wohnung zum Zentrum, wo das Licht von Ostern leuchtet. Die Gegenwart des Auferstandenen ist die wahre gute Nachricht, die unser geistliches Leben wiederbeleben kann. Die Meditationen wurden von P. Guillaume Dehorter OCD (Karmelit in Avon bei Paris) und einem Team zusammengestellt. Die Aussendung in deutscher Sprache geschieht als Initiative des Verlags Christliche Innerlichkeit und des Teresianischen Karmel in Österreich, der Edith Stein Gesellschaft Österreich und der Marienschwestern vom Karmel. Die deutsche Fassung wurde von den Karmelitinnen in Mayerling bereitgestellt. | BF13: Durante esta Cuaresma nos acompañara las enseñanzas de Santa Teresa de Ávila (1515-1582, gran mística y maestra de oración que nos alentará a adentrarnos en nosotros mismos y fijar la mirada en “Aquel que sabemos nos Ama”infinitamente, nuestro modelo y camino de toda vida cristiana. Fue en medio de una gran crisis que Teresa de Jesús escribió su obra maestra espiritual, Las Moradas. Cuando parece que la obra fundacional de sus “Carmelos” parece desmoronarse, la Santa extrae toda su fortaleza de su Castillo Interior. En nuestro contexto de crisis sanitaria y económica, la Santa Madre puede ayudarnos durante esta Cuaresma a descubrir que nuestra fuerza está en nuestro interior. Con esta Doctora de la Iglesia, caminaremos de morada en morada hasta el centro donde resplandece la luz de la Pascua. La presencia del Resucitado es la verdadera Buena Noticia que puede revitalizar nuestra vida espiritual. ¡Qué esta Cuaresma sea un tiempo en el que experimentemos la amistad con Dios hasta convertirnos en sus compañeros de camino de entrega! | BT13: ../img/FS21_header_FR.png | BU13: ../de/img/FS21_header_DE.jpg | BV13: ../es/img/2021_lent_header_ES.jpg | BW13: ../it/img/FS21_header_IT.png | BX13: ../img/FS21_header_EN.png | BY13: ../img/FS21_header_PL.png | BZ13: ../img/FS21_header_AR.png | CA13: ../img/FS21_header_PT.png | CB13: ../img/FS21_header_ZH.png | CC13: ../img/FS21_header_CS.png | CD13: ../img/FS21_header_HR.png | CE13: ../img/FS21_header_HU.png | CF13: ../img/FS21_header_MT.png | CG13: ../img/FS21_header_NL.png | CH13: ../img/FS21_header_RO.png | CI13: ../img/FS21_header_VI.png
A14: advent-2020-madame-acarie | B14: advent | C14: 2020 | E14: 2020_advent | F14: 2020_adviento | G14: 2020_avvento | H14: 2020_advent | I14: 2020_adwent | J14: 2020_zaman-al-maji | K14: 2020_advento | L14: 2020_jianglinqi | M14: 2020_advent | N14: 2020_dosasce | O14: 2020_advent | P14: 2020_avvent | Q14: 2020_advent | R14: 2020_advent | S14: 2020_mua-vong | T14: Maria von der Menschwerdung | W14: X:\ALLGEMEIN\0900 Veröffentlichungen\Veröffentlichungen-aktuell\2020 Advent | X14: Avent 2020 | Y14: Advent 2020 mit der "Schönen Acarie" (1566-1618) | AN14: Madame Acarie | AO14: Glauben an das Unmögliche | BE14: Diesmal begleitet uns durch den Advent die Gründerin des Karmel in Frankreich, Sr. Maria von der Menschwerdung (1566-1618), auch die “Schöne Acarie” genannt. Sie heiratete, bekamm Kinder und war in der Gesellshaft ihrer Zeit sehr einflussreich, bevor sie schließlich als Witwe in den Karmel eintrat. Ihre Biographie und ihre geistlichen Schriften geben Nahrung besonders in einer Zeit wie dieser, die von Unsicherheit geprägt ist. Die Exerzitien stehen unter dem Motto: Glauben an das Unmögliche. | BT14: ../img/AD20_header_FR.png | BU14: ../de/img/AD20_header_DE.jpg | BV14: ../img/AD20_header_ES.png | BW14: ../it/img/AD20_header_IT.png | BX14: ../img/AD20_header_EN.png | BY14: ../img/AD20_header_PL.png | BZ14: ../img/AD20_header_AR.png | CA14: ../img/AD20_header_PT.png | CB14: ../img/AD20_header_ZH.png | CC14: ../img/AD20_header_CS.png | CD14: ../img/AD20_header_HR.png | CE14: ../img/AD20_header_HU.png | CF14: ../img/AD20_header_MT.png | CG14: ../img/AD20_header_NL.png | CH14: ../img/AD20_header_RO.png | CI14: ../img/AD20_header_VI.png
A15: lent-2020-heureuse-aventure | B15: lent | C15: 2020 | D15: https://retraites.carmes-paris.org/careme-2020/careme-2020-st-jean-de-la-croix/ | E15: 2020_fastenzeit | F15: 2020_cuaresma | G15: 2020_quaresima | H15: 2020_lent | I15: 2020_wielki-post | J15: 2020_al-sawm-al-kabir | K15: 2020_quaresma | L15: 2020_sixunqi | M15: 2020_pust | N15: 2020_korizma | O15: 2020_nagybojt | P15: 2020_randan | Q15: 2020_vastentijd | R15: 2020_postul-mare | S15: 2020_mua-chay | T15: Heiliger Johannes vom Kreuz | W15: X:\ALLGEMEIN\0900 Veröffentlichungen\Veröffentlichungen-aktuell\2020 Fasten | X15: Carême 2020 | Y15: Fastenzeit 2020 mit dem Hl. Johannes vom Kreuz | AN15: Oser « l’heureuse aventure » avec saint Jean de la Croix | AO15: die Liebe wagen... | BE15: In dieser Fastenzeit werden uns Texte des hl. Karmeliten Johannes vom Kreuz begleiten, der im XVI. Jhd. zusammen mit der hl. Teresa von Avila den Orden der Karmelitinnen und Karmeliten reformiert hat. Als Lehrer der Kirche gilt er besonders als Meister des mystischen Lebens und wird heute noch von vielen als Berater im Geistlichen Leben angerufen bzw. werden seine Werke gelesen. | BT15: ../img/FS20_header_FR.png | BU15: ../de/img/FS20_header_DE.jpg | BV15: ../img/FS20_header_ES.png | BW15: ../it/img/FS20_header_IT.png | BX15: ../img/FS20_header_EN.png | BY15: ../img/FS20_header_PL.png | BZ15: ../img/FS20_header_AR.png | CA15: ../img/FS20_header_PT.png | CB15: ../img/FS20_header_ZH.png | CC15: ../img/FS20_header_CS.png | CD15: ../img/FS20_header_HR.png | CE15: ../img/FS20_header_HU.png | CF15: ../img/FS20_header_MT.png | CG15: ../img/FS20_header_NL.png | CH15: ../img/FS20_header_RO.png | CI15: ../img/FS20_header_VI.png
A16: advent-2019-communier-a-la-vie-de-grace-de-marie | B16: advent | C16: 2019 | E16: 2019_advent | F16: 2019_adviento | G16: 2019_avvento | H16: 2019_advent | I16: 2019_adwent | J16: 2019_zaman-al-maji | K16: 2019_advento | L16: 2019_jianglinqi | M16: 2019_advent | N16: 2019_dosasce | O16: 2019_advent | P16: 2019_avvent | Q16: 2019_advent | R16: 2019_advent | S16: 2019_mua-vong | T16: Unsere Liebe Frau vom Berge Karmel | W16: X:\ALLGEMEIN\0900 Veröffentlichungen\Veröffentlichungen-aktuell\2019 Advent | X16: Avent 2019 | Y16: Advent 2019 mit Unserer Lieben Frau vom Berge Karmel | AN16: "Communier à la vie de grâce de Marie" avec François de Sainte-Marie, ocd (1910-1961) | AO16: Am Gnadenleben Mariens teilhaben | BE16: Wer ist qualifizierter als die Mutter Jesu, die Jungfrau Maria, um uns auf Weihnachten vorzubereiten? Unsere liebe Frau vom Berge Karmel begleitet uns in diesen neuen Adventsexerzitien und hilft uns, das Wort Gottes zu verinnerlichen und es in die Tat umzusetzen. Wir werden das Geheimnis Mariens mithilfe der Schriften des Karmeliten P. François de S.te Marie OCD näher kennenlernen. | BT16: ../img/AD19_header_FR.png | BU16: ../de/img/AD19_header_DE.jpg | BV16: ../img/AD19_header_ES.png | BW16: ../it/img/AD19_header_IT.png | BX16: ../img/AD19_header_EN.png | BY16: ../img/AD19_header_PL.png | BZ16: ../img/AD19_header_AR.png | CA16: ../img/AD19_header_PT.png | CB16: ../img/AD19_header_ZH.png | CC16: ../img/AD19_header_CS.png | CD16: ../img/AD19_header_HR.png | CE16: ../img/AD19_header_HU.png | CF16: ../img/AD19_header_MT.png | CG16: ../img/AD19_header_NL.png | CH16: ../img/AD19_header_RO.png | CI16: ../img/AD19_header_VI.png
A17: lent-2019-edith-stein | B17: lent | C17: 2019 | D17: https://retraites.carmes-paris.org/careme-2019/careme-2019-st-jean-de-la-croix/ | E17: 2019_fastenzeit | F17: 2019_cuaresma | G17: 2019_quaresima | H17: 2019_lent | I17: 2019_wielki-post | J17: 2019_al-sawm-al-kabir | K17: 2019_quaresma | L17: 2019_sixunqi | M17: 2019_pust | N17: 2019_korizma | O17: 2019_nagybojt | P17: 2019_randan | Q17: 2019_vastentijd | R17: 2019_postul-mare | S17: 2019_mua-chay | T17: Heilige Teresa-Benedicta vom Kreuz (Edith Stein) | W17: X:\ALLGEMEIN\0900 Veröffentlichungen\Veröffentlichungen-aktuell\2019 Fasten | X17: Carême 2019 | Y17: Fastenzeit 2019 mit Edith Stein Hl. Teresa-Benedicta vom Kreuz | AN17: Carême avec sainte Édith Stein | AO17: Der Auferstehung entgegen mit Edith Stein Hl. Teresa-Benedicta vom Kreuz | BE17: Die Hl. Teresa Benedicta vom Kreuz ist eine Mit-Patronin von Europa. Bevor sie in den Karmel eintrat und ihren Ordensnamen angenommen hat, war Edith Stein Philosophin und Dozentin. Sie wurde 1981 in Preussen als Jüdin geboren und wandte sich später dem Agnostizismus zu. Sie begab sich auf die Suche nach Wahrheit, durch die Philosophie und die Ereignisse in ihrem Leben, bis sie schließlich Christus entdeckte und sich im Alter von 31 Jahren taufen ließ. Sie wurde eine bemerkenswerte katholische Intellektuelle, der von den Nazis die Lehrerlaubnis entzogen wurde. Im Jahr 1933 trat sie in den Kölner Karmel ein, von wo sie 1939 nach Holland in den Karmel in Echt fliehen musste. Dort wurden sie und ihre Schwester festgenommen und nach Auschwitz gebracht, wo Edith Stein am 9. August 1942 starb. Hinterlassen hat sie uns ihr Werk und eine starke Botschaft. In dieser Fastenzeit werden uns ihre Schriften und ihr Leben begleiten, wenn wir uns auf den Weg machen, Christus nachzufolgen, der Auferstehung entgegen. | BT17: ../img/FS19_header_FR.png | BU17: ../de/img/FS19_header_DE.jpg | BV17: ../img/FS19_header_ES.png | BW17: ../it/img/FS19_header_IT.png | BX17: ../img/FS19_header_EN.png | BY17: ../img/FS19_header_PL.png | BZ17: ../img/FS19_header_AR.png | CA17: ../img/FS19_header_PT.png | CB17: ../img/FS19_header_ZH.png | CC17: ../img/FS19_header_CS.png | CD17: ../img/FS19_header_HR.png | CE17: ../img/FS19_header_HU.png | CF17: ../img/FS19_header_MT.png | CG17: ../img/FS19_header_NL.png | CH17: ../img/FS19_header_RO.png | CI17: ../img/FS19_header_VI.png
A18: advent-2018-mont-carmel | B18: advent | C18: 2018 | E18: 2018_advent | F18: 2018_adviento | G18: 2018_avvento | H18: 2018_advent | I18: 2018_adwent | J18: 2018_zaman-al-maji | K18: 2018_advento | L18: 2018_jianglinqi | M18: 2018_advent | N18: 2018_dosasce | O18: 2018_advent | P18: 2018_avvent | Q18: 2018_advent | R18: 2018_advent | S18: 2018_mua-vong | T18: Unsere Liebe Frau vom Berge Karmel | W18: X:\ALLGEMEIN\0900 Veröffentlichungen\Veröffentlichungen-aktuell\2018 Advent | X18: Avent 2018 | Y18: Advent 2018 mit Unserer Lieben Frau vom Berge Karmel | AN18: Avec Notre-Dame du Mont Carmel – Préparer le chemin du Seigneur | AO18: Den Weg des Herrn vorbereiten | BE18: Wer ist qualifizierter als die Mutter Jesu, die Jungfrau Maria, um uns auf Weihnachten vorzubereiten? Nach dem heiligen Josef im vergangenen Jahr, begleitet sie uns in diesen neuen Adventsexerzitien. Unsere liebe Frau vom Berge Karmel hilft uns, das Wort Gottes zu verinnerlichen und es in die Tat umzusetzen. Wir werden das Geheimnis Mariens anhand des mittelalterlichen Gedichtes „Flos carmeli“ meditieren, das sie als Blume, Königin und Schönheit des Karmel anruft. So werden wir noch mehr entdecken, wie sehr Christus uns in unserer Menschheit begegnet. | BT18: ../img/AD18_header_FR.png | BU18: ../de/img/AD18_header_DE.jpg | BV18: ../img/AD18_header_ES.png | BW18: ../it/img/AD18_header_IT.png | BX18: ../img/AD18_header_EN.png | BY18: ../img/AD18_header_PL.png | BZ18: ../img/AD18_header_AR.png | CA18: ../img/AD18_header_PT.png | CB18: ../img/AD18_header_ZH.png | CC18: ../img/AD18_header_CS.png | CD18: ../img/AD18_header_HR.png | CE18: ../img/AD18_header_HU.png | CF18: ../img/AD18_header_MT.png | CG18: ../img/AD18_header_NL.png | CH18: ../img/AD18_header_RO.png | CI18: ../img/AD18_header_VI.png
A19: lent-2018-laurent-de-la-resurrection | B19: lent | C19: 2018 | D19: https://retraites.carmes-paris.org/careme-2018/careme-2018-st-jean-de-la-croix/ | E19: 2018_fastenzeit | F19: 2018_cuaresma | G19: 2018_quaresima | H19: 2018_lent | I19: 2018_wielki-post | J19: 2018_al-sawm-al-kabir | K19: 2018_quaresma | L19: 2018_sixunqi | M19: 2018_pust | N19: 2018_korizma | O19: 2018_nagybojt | P19: 2018_randan | Q19: 2018_vastentijd | R19: 2018_postul-mare | S19: 2018_mua-chay | T19: Br. Lorenz von der Auferstehung | W19: X:\ALLGEMEIN\0900 Veröffentlichungen\Veröffentlichungen-aktuell\2018 Fasten | X19: Carême 2018 | Y19: Fastenzeit 2018 mit Br. Lorenz von der Auferstehung | AA19: Quaresima 2018 con fra Lorenzo della Risurrezione | AN19: Avec Laurent de la Résurrection – Vivre toute chose en présence du Seigneur | AO19: Sich von Gott formen lassen | AQ19: Lasciarsi plasmare da Dio | BE19: «Ich wende mein kleines Omelett in der Pfanne aus Liebe zu Gott» Bruder Lorenz von der Auferstehung der „mystische Koch” | BG19: Compilando il modulo qui sotto vi iscriverete gratuiramente agli “esercizi spirituali online” per la quaresima 2018. Quest’anno ci accompagnerà il carmelitano fra Lorenzo della Risurrezione (161-1691) . “Fra Lorenzo” “Brother Lawrence”: è stranamente più conosciuto in ambiente angolsassone che in Francia, la propria patria! Eppure fra Lorenzo della Risurrezione (1614-1691) ha vissuto la parte essenziale della sua vita nel convento degli scalzi di Parigi. È lì che ha scoperto e poi insegnato ciò che verrà chiamata “la pratica della presenza di Dio”. Questo umile frate prima cuoco e poi calzolaio esercitò una grande influenza durante la sua vita e il suo messaggio è arrivato sino a noi. Ci aiuta a vivere gli aspetti più banali della vita quotidiana sotto lo sguardo di Dio. La preghiera non è più confinata a tempi specifici. È tutta la nostra esistenza che diventa una relazione viva con il Signore. Durante questa quaresima, ci lasceremo plasmare da questo Mistero! | BT19: ../img/FS18_header_FR.png | BU19: ../de/img/FS18_header_DE.jpg | BV19: ../img/FS18_header_ES.png | BW19: ../it/img/FS18_header_IT.png | BX19: ../img/FS18_header_EN.png | BY19: ../img/FS18_header_PL.png | BZ19: ../img/FS18_header_AR.png | CA19: ../img/FS18_header_PT.png | CB19: ../img/FS18_header_ZH.png | CC19: ../img/FS18_header_CS.png | CD19: ../img/FS18_header_HR.png | CE19: ../img/FS18_header_HU.png | CF19: ../img/FS18_header_MT.png | CG19: ../img/FS18_header_NL.png | CH19: ../img/FS18_header_RO.png | CI19: ../img/FS18_header_VI.png
